Workbook
Name Plage_BoissonJus: tbl_BoissonJus!$A$1:$F$181
Name Plage_GauffreCrepe: 'tbl_GaufCre&Dsrt'!$A$1:$F$198
Name Plage_Marocains: 'tbl_Taj&Pla'!$A$1:$F$345
Name Plage_PtiDej: 'tbl_PtDj&Sup'!$A$1:$F$168
Name Plage_Snack: 'tbl_Snk&Ita'!$A$1:$F$300

Sheet Dashboard
B1: Date début | C1: Date fin
B2: 45931 | C2: 45961
B3: Total charges fixes mensuelles | C3: Total CA sur la période | F3: Charges fixes par portion | G3: Charge Fixes par Portion
B4: =SUM(tbl_Charges_Fixes[Montant_Mensuel]) -> 929242 | C4: =IFERROR(SUMIFS(tbl_Ventes[CA ligne], tbl_Ventes[Date], ">="&$B$2, tbl_Ventes[Date], "<="&$C$2),"Vérifier") -> 1242446 | D4: Charges fixes de la période | F4: =IFERROR(SUMIFS(tbl_Ventes[Qté Vendue], tbl_Ventes[Date], ">="&$B$2, tbl_Ventes[Date], "<="&$C$2),0) -> 10787 | G4: =IF(SUMIFS(tbl_Ventes[Qté Vendue], tbl_Ventes[Date], ">="&$B$2, tbl_Ventes[Date], "<="&$C$2)=0, 0, tbl_Charges_Fixes[[#Totals],[Montant_Mensuel]] / SUMIFS(tbl_Ventes[Qté Vendue], tbl_Ventes[Date], ">="&$B$2, tbl_Ventes[Date], "<="&$C$2)) -> 86.144619
B5: Nombre de jours analysés | C5: =MAX(1, $C$2 - $B$2 + 1) -> 31 | D5: =B4 * C5 / 30 -> 960216.73
A7: Total CA | B7: Coût matière total | C7: Marge brute total | D7: % marge brute | E7: Food cost % | F7: Total charges fixes mensuelles | G7: Marge nette après charges
A8: =+$C$4 -> 1242446 | B8: =IFERROR(SUMIFS(tbl_Ventes[Coût matière ligne], tbl_Ventes[Date], ">="&$B$2, tbl_Ventes[Date], "<="&$C$2),"Vérifier") -> 1023679.7 | C8: =IFERROR($A$8- $B$8,"Vérifier") -> 218766.3 | D8: =IFERROR(IF(tbl_Kpi[[#This Row],[Total CA]]=0, 0, tbl_Kpi[[#This Row],[Marge brute total]] / tbl_Kpi[[#This Row],[Total CA]]),"Vérifier") -> 0.17607711 | E8: =IFERROR(IF(tbl_Kpi[[#This Row],[Total CA]]>0, tbl_Kpi[[#This Row],[Coût matière total]]/tbl_Kpi[[#This Row],[Total CA]]),"Vérifier") -> 0.82392289 | F8: =$B$4 -> 929242 | G8: =IFERROR(tbl_Kpi[[#This Row],[Marge brute total]] - tbl_Kpi[[#This Row],[Total charges fixes mensuelles]],"Vérifier") -> -710475.7
A10: Famille | B10: CA Famille | C10: Coût matière Famille | D10: Marge brute famille | E10: Charges globales réparties | F10: Charges spécifiques | G10: Charges totales | H10: Marge nette
A11: Petits déjeuners | B11: =SUMIF(tbl_Ventes[Famille], tbl_Famille[[#This Row],[Famille]], tbl_Ventes[CA ligne]) -> 62640 | C11: =IFERROR(SUMIF(tbl_Ventes[Famille], tbl_Famille[[#This Row],[Famille]], tbl_Ventes[Coût matière ligne]),"Vérifier") -> 28420 | D11: =IFERROR(tbl_Famille[[#This Row],[CA Famille]] - tbl_Famille[[#This Row],[Coût matière Famille]],"Vérifier") -> 34220 | E11: =SUMIF(tbl_Charges_Fixes[Type d’affectation],"Globale",tbl_Charges_Fixes[Montant_Mensuel]) -> 498592 | F11: =IFERROR(SUMIFS(tbl_Charges_Fixes[Montant_Mensuel], tbl_Charges_Fixes[Type d’affectation], "Spécifique", tbl_Charges_Fixes[Famille affectée], tbl_Famille[[#This Row],[Famille]]),"Vérifier") -> 24000 | G11: =IFERROR(tbl_Famille[[#This Row],[Charges globales réparties]] + tbl_Famille[[#This Row],[Charges spécifiques]],"Vérifier") -> 522592 | H11: =IFERROR(tbl_Famille[[#This Row],[Marge brute famille]] - tbl_Famille[[#This Row],[Charges totales]],"Vérifier") -> -488372
A12: Œufs & Omelettes | B12: =SUMIF(tbl_Ventes[Famille], tbl_Famille[[#This Row],[Famille]], tbl_Ventes[CA ligne]) -> 3546 | C12: =IFERROR(SUMIF(tbl_Ventes[Famille], tbl_Famille[[#This Row],[Famille]], tbl_Ventes[Coût matière ligne]),"Vérifier") -> 1616.51 | D12: =IFERROR(tbl_Famille[[#This Row],[CA Famille]] - tbl_Famille[[#This Row],[Coût matière Famille]],"Vérifier") -> 1929.49 | E12: =SUMIF(tbl_Charges_Fixes[Type d’affectation],"Globale",tbl_Charges_Fixes[Montant_Mensuel]) -> 498592 | F12: =IFERROR(SUMIFS(tbl_Charges_Fixes[Montant_Mensuel], tbl_Charges_Fixes[Type d’affectation], "Spécifique", tbl_Charges_Fixes[Famille affectée], tbl_Famille[[#This Row],[Famille]]),"Vérifier") -> 24000 | G12: =IFERROR(tbl_Famille[[#This Row],[Charges globales réparties]] + tbl_Famille[[#This Row],[Charges spécifiques]],"Vérifier") -> 522592 | H12: =IFERROR(tbl_Famille[[#This Row],[Marge brute famille]] - tbl_Famille[[#This Row],[Charges totales]],"Vérifier") -> -520662.51
A13: à la carte | B13: =SUMIF(tbl_Ventes[Famille], tbl_Famille[[#This Row],[Famille]], tbl_Ventes[CA ligne]) -> 9100 | C13: =IFERROR(SUMIF(tbl_Ventes[Famille], tbl_Famille[[#This Row],[Famille]], tbl_Ventes[Coût matière ligne]),"Vérifier") -> 12090 | D13: =IFERROR(tbl_Famille[[#This Row],[CA Famille]] - tbl_Famille[[#This Row],[Coût matière Famille]],"Vérifier") -> -2990 | E13: =SUMIF(tbl_Charges_Fixes[Type d’affectation],"Globale",tbl_Charges_Fixes[Montant_Mensuel]) -> 498592 | F13: =IFERROR(SUMIFS(tbl_Charges_Fixes[Montant_Mensuel], tbl_Charges_Fixes[Type d’affectation], "Spécifique", tbl_Charges_Fixes[Famille affectée], tbl_Famille[[#This Row],[Famille]]),"Vérifier") -> 24000 | G13: =IFERROR(tbl_Famille[[#This Row],[Charges globales réparties]] + tbl_Famille[[#This Row],[Charges spécifiques]],"Vérifier") -> 522592 | H13: =IFERROR(tbl_Famille[[#This Row],[Marge brute famille]] - tbl_Famille[[#This Row],[Charges totales]],"Vérifier") -> -525582
A14: Suppléments | B14: =SUMIF(tbl_Ventes[Famille], tbl_Famille[[#This Row],[Famille]], tbl_Ventes[CA ligne]) -> 4158 | C14: =IFERROR(SUMIF(tbl_Ventes[Famille], tbl_Famille[[#This Row],[Famille]], tbl_Ventes[Coût matière ligne]),"Vérifier") -> 10834 | D14: =IFERROR(tbl_Famille[[#This Row],[CA Famille]] - tbl_Famille[[#This Row],[Coût matière Famille]],"Vérifier") -> -6676 | E14: =SUMIF(tbl_Charges_Fixes[Type d’affectation],"Globale",tbl_Charges_Fixes[Montant_Mensuel]) -> 498592 | F14: =IFERROR(SUMIFS(tbl_Charges_Fixes[Montant_Mensuel], tbl_Charges_Fixes[Type d’affectation], "Spécifique", tbl_Charges_Fixes[Famille affectée], tbl_Famille[[#This Row],[Famille]]),"Vérifier") -> 0 | G14: =IFERROR(tbl_Famille[[#This Row],[Charges globales réparties]] + tbl_Famille[[#This Row],[Charges spécifiques]],"Vérifier") -> 498592 | H14: =IFERROR(tbl_Famille[[#This Row],[Marge brute famille]] - tbl_Famille[[#This Row],[Charges totales]],"Vérifier") -> -505268
A15: Entrées & Salades | B15: =SUMIF(tbl_Ventes[Famille], tbl_Famille[[#This Row],[Famille]], tbl_Ventes[CA ligne]) -> 0 | C15: =IFERROR(SUMIF(tbl_Ventes[Famille], tbl_Famille[[#This Row],[Famille]], tbl_Ventes[Coût matière ligne]),"Vérifier") -> 0 | D15: =IFERROR(tbl_Famille[[#This Row],[CA Famille]] - tbl_Famille[[#This Row],[Coût matière Famille]],"Vérifier") -> 0 | E15: =SUMIF(tbl_Charges_Fixes[Type d’affectation],"Globale",tbl_Charges_Fixes[Montant_Mensuel]) -> 498592 | F15: =IFERROR(SUMIFS(tbl_Charges_Fixes[Montant_Mensuel], tbl_Charges_Fixes[Type d’affectation], "Spécifique", tbl_Charges_Fixes[Famille affectée], tbl_Famille[[#This Row],[Famille]]),"Vérifier") -> 40000 | G15: =IFERROR(tbl_Famille[[#This Row],[Charges globales réparties]] + tbl_Famille[[#This Row],[Charges spécifiques]],"Vérifier") -> 538592 | H15: =IFERROR(tbl_Famille[[#This Row],[Marge brute famille]] - tbl_Famille[[#This Row],[Charges totales]],"Vérifier") -> -538592
A16: Poulet | B16: =SUMIF(tbl_Ventes[Famille], tbl_Famille[[#This Row],[Famille]], tbl_Ventes[CA ligne]) -> 0 | C16: =IFERROR(SUMIF(tbl_Ventes[Famille], tbl_Famille[[#This Row],[Famille]], tbl_Ventes[Coût matière ligne]),"Vérifier") -> 0 | D16: =IFERROR(tbl_Famille[[#This Row],[CA Famille]] - tbl_Famille[[#This Row],[Coût matière Famille]],"Vérifier") -> 0 | E16: =SUMIF(tbl_Charges_Fixes[Type d’affectation],"Globale",tbl_Charges_Fixes[Montant_Mensuel]) -> 498592 | F16: =IFERROR(SUMIFS(tbl_Charges_Fixes[Montant_Mensuel], tbl_Charges_Fixes[Type d’affectation], "Spécifique", tbl_Charges_Fixes[Famille affectée], tbl_Famille[[#This Row],[Famille]]),"Vérifier") -> 24000 | G16: =IFERROR(tbl_Famille[[#This Row],[Charges globales réparties]] + tbl_Famille[[#This Row],[Charges spécifiques]],"Vérifier") -> 522592 | H16: =IFERROR(tbl_Famille[[#This Row],[Marge brute famille]] - tbl_Famille[[#This Row],[Charges totales]],"Vérifier") -> -522592
A17: Boucherie | B17: =SUMIF(tbl_Ventes[Famille], tbl_Famille[[#This Row],[Famille]], tbl_Ventes[CA ligne]) -> 537660 | C17: =IFERROR(SUMIF(tbl_Ventes[Famille], tbl_Famille[[#This Row],[Famille]], tbl_Ventes[Coût matière ligne]),"Vérifier") -> 743000 | D17: =IFERROR(tbl_Famille[[#This Row],[CA Famille]] - tbl_Famille[[#This Row],[Coût matière Famille]],"Vérifier") -> -205340 | E17: =SUMIF(tbl_Charges_Fixes[Type d’affectation],"Globale",tbl_Charges_Fixes[Montant_Mensuel]) -> 498592 | F17: =IFERROR(SUMIFS(tbl_Charges_Fixes[Montant_Mensuel], tbl_Charges_Fixes[Type d’affectation], "Spécifique", tbl_Charges_Fixes[Famille affectée], tbl_Famille[[#This Row],[Famille]]),"Vérifier") -> 6540 | G17: =IFERROR(tbl_Famille[[#This Row],[Charges globales réparties]] + tbl_Famille[[#This Row],[Charges spécifiques]],"Vérifier") -> 505132 | H17: =IFERROR(tbl_Famille[[#This Row],[Marge brute famille]] - tbl_Famille[[#This Row],[Charges totales]],"Vérifier") -> -710472
A18: Poissons & Fruits de mer | B18: =SUMIF(tbl_Ventes[Famille], tbl_Famille[[#This Row],[Famille]], tbl_Ventes[CA ligne]) -> 0 | C18: =IFERROR(SUMIF(tbl_Ventes[Famille], tbl_Famille[[#This Row],[Famille]], tbl_Ventes[Coût matière ligne]),"Vérifier") -> 0 | D18: =IFERROR(tbl_Famille[[#This Row],[CA Famille]] - tbl_Famille[[#This Row],[Coût matière Famille]],"Vérifier") -> 0 | E18: =SUMIF(tbl_Charges_Fixes[Type d’affectation],"Globale",tbl_Charges_Fixes[Montant_Mensuel]) -> 498592 | F18: =IFERROR(SUMIFS(tbl_Charges_Fixes[Montant_Mensuel], tbl_Charges_Fixes[Type d’affectation], "Spécifique", tbl_Charges_Fixes[Famille affectée], tbl_Famille[[#This Row],[Famille]]),"Vérifier") -> 6555 | G18: =IFERROR(tbl_Famille[[#This Row],[Charges globales réparties]] + tbl_Famille[[#This Row],[Charges spécifiques]],"Vérifier") -> 505147 | H18: =IFERROR(tbl_Famille[[#This Row],[Marge brute famille]] - tbl_Famille[[#This Row],[Charges totales]],"Vérifier") -> -505147
A19: Tajines & Coin marocain | B19: =SUMIF(tbl_Ventes[Famille], tbl_Famille[[#This Row],[Famille]], tbl_Ventes[CA ligne]) -> 550200 | C19: =IFERROR(SUMIF(tbl_Ventes[Famille], tbl_Famille[[#This Row],[Famille]], tbl_Ventes[Coût matière ligne]),"Vérifier") -> 191475.98 | D19: =IFERROR(tbl_Famille[[#This Row],[CA Famille]] - tbl_Famille[[#This Row],[Coût matière Famille]],"Vérifier") -> 358724.02 | E19: =SUMIF(tbl_Charges_Fixes[Type d’affectation],"Globale",tbl_Charges_Fixes[Montant_Mensuel]) -> 498592 | F19: =IFERROR(SUMIFS(tbl_Charges_Fixes[Montant_Mensuel], tbl_Charges_Fixes[Type d’affectation], "Spécifique", tbl_Charges_Fixes[Famille affectée], tbl_Famille[[#This Row],[Famille]]),"Vérifier") -> 65555 | G19: =IFERROR(tbl_Famille[[#This Row],[Charges globales réparties]] + tbl_Famille[[#This Row],[Charges spécifiques]],"Vérifier") -> 564147 | H19: =IFERROR(tbl_Famille[[#This Row],[Marge brute famille]] - tbl_Famille[[#This Row],[Charges totales]],"Vérifier") -> -205422.98
A20: Pâtes | B20: =SUMIF(tbl_Ventes[Famille], tbl_Famille[[#This Row],[Famille]], tbl_Ventes[CA ligne]) -> 0 | C20: =IFERROR(SUMIF(tbl_Ventes[Famille], tbl_Famille[[#This Row],[Famille]], tbl_Ventes[Coût matière ligne]),"Vérifier") -> 0 | D20: =IFERROR(tbl_Famille[[#This Row],[CA Famille]] - tbl_Famille[[#This Row],[Coût matière Famille]],"Vérifier") -> 0 | E20: =SUMIF(tbl_Charges_Fixes[Type d’affectation],"Globale",tbl_Charges_Fixes[Montant_Mensuel]) -> 498592 | F20: =IFERROR(SUMIFS(tbl_Charges_Fixes[Montant_Mensuel], tbl_Charges_Fixes[Type d’affectation], "Spécifique", tbl_Charges_Fixes[Famille affectée], tbl_Famille[[#This Row],[Famille]]),"Vérifier") -> 21000 | G20: =IFERROR(tbl_Famille[[#This Row],[Charges globales réparties]] + tbl_Famille[[#This Row],[Charges spécifiques]],"Vérifier") -> 519592 | H20: =IFERROR(tbl_Famille[[#This Row],[Marge brute famille]] - tbl_Famille[[#This Row],[Charges totales]],"Vérifier") -> -519592
A21: Pizzas | B21: =SUMIF(tbl_Ventes[Famille], tbl_Famille[[#This Row],[Famille]], tbl_Ventes[CA ligne]) -> 0 | C21: =IFERROR(SUMIF(tbl_Ventes[Famille], tbl_Famille[[#This Row],[Famille]], tbl_Ventes[Coût matière ligne]),"Vérifier") -> 0 | D21: =IFERROR(tbl_Famille[[#This Row],[CA Famille]] - tbl_Famille[[#This Row],[Coût matière Famille]],"Vérifier") -> 0 | E21: =SUMIF(tbl_Charges_Fixes[Type d’affectation],"Globale",tbl_Charges_Fixes[Montant_Mensuel]) -> 498592 | F21: =IFERROR(SUMIFS(tbl_Charges_Fixes[Montant_Mensuel], tbl_Charges_Fixes[Type d’affectation], "Spécifique", tbl_Charges_Fixes[Famille affectée], tbl_Famille[[#This Row],[Famille]]),"Vérifier") -> 21000 | G21: =IFERROR(tbl_Famille[[#This Row],[Charges globales réparties]] + tbl_Famille[[#This Row],[Charges spécifiques]],"Vérifier") -> 519592 | H21: =IFERROR(tbl_Famille[[#This Row],[Marge brute famille]] - tbl_Famille[[#This Row],[Charges totales]],"Vérifier") -> -519592
A22: Snack | B22: =SUMIF(tbl_Ventes[Famille], tbl_Famille[[#This Row],[Famille]], tbl_Ventes[CA ligne]) -> 0 | C22: =IFERROR(SUMIF(tbl_Ventes[Famille], tbl_Famille[[#This Row],[Famille]], tbl_Ventes[Coût matière ligne]),"Vérifier") -> 0 | D22: =IFERROR(tbl_Famille[[#This Row],[CA Famille]] - tbl_Famille[[#This Row],[Coût matière Famille]],"Vérifier") -> 0 | E22: =SUMIF(tbl_Charges_Fixes[Type d’affectation],"Globale",tbl_Charges_Fixes[Montant_Mensuel]) -> 498592 | F22: =IFERROR(SUMIFS(tbl_Charges_Fixes[Montant_Mensuel], tbl_Charges_Fixes[Type d’affectation], "Spécifique", tbl_Charges_Fixes[Famille affectée], tbl_Famille[[#This Row],[Famille]]),"Vérifier") -> 20000 | G22: =IFERROR(tbl_Famille[[#This Row],[Charges globales réparties]] + tbl_Famille[[#This Row],[Charges spécifiques]],"Vérifier") -> 518592 | H22: =IFERROR(tbl_Famille[[#This Row],[Marge brute famille]] - tbl_Famille[[#This Row],[Charges totales]],"Vérifier") -> -518592
... A29: Boissons froides | B29: =SUMIF(tbl_Ventes[Famille], tbl_Famille[[#This Row],[Famille]], tbl_Ventes[CA ligne]) -> 0 | C29: =IFERROR(SUMIF(tbl_Ventes[Famille], tbl_Famille[[#This Row],[Famille]], tbl_Ventes[Coût matière ligne]),"Vérifier") -> 0 | D29: =IFERROR(tbl_Famille[[#This Row],[CA Famille]] - tbl_Famille[[#This Row],[Coût matière Famille]],"Vérifier") -> 0 | E29: =SUMIF(tbl_Charges_Fixes[Type d’affectation],"Globale",tbl_Charges_Fixes[Montant_Mensuel]) -> 498592 | F29: =IFERROR(SUMIFS(tbl_Charges_Fixes[Montant_Mensuel], tbl_Charges_Fixes[Type d’affectation], "Spécifique", tbl_Charges_Fixes[Famille affectée], tbl_Famille[[#This Row],[Famille]]),"Vérifier") -> 40000 | G29: =IFERROR(tbl_Famille[[#This Row],[Charges globales réparties]] + tbl_Famille[[#This Row],[Charges spécifiques]],"Vérifier") -> 538592 | H29: =IFERROR(tbl_Famille[[#This Row],[Marge brute famille]] - tbl_Famille[[#This Row],[Charges totales]],"Vérifier") -> -538592

Sheet tbl_Ventes
A1: Date | B1: Mois | C1: Produit | D1: Cde_Prdt | E1: Qté Vendue | F1: Prix Menu | G1: CA ligne | H1: CMP_par_portion | I1: Coût matière ligne | J1: Marge ligne | K1: Famille
A2: 45955 | B2: =IFERROR(TEXT(tbl_Ventes[[#This Row],[Date]],"mm-aaaa"),"") -> 10-2025 | C2: Viennoiserie G | D2: =IFERROR( INDEX(tbl_ProduitsRef[Cde_Prdt],MATCH(tbl_Ventes[[#This Row],[Produit]],tbl_ProduitsRef[Produit],0)), "" ) -> SUP005 | E2: 33 | F2: =IFERROR( INDEX(tbl_ProduitsRef[Prix Menu],MATCH(tbl_Ventes[[#This Row],[Produit]],tbl_ProduitsRef[Produit],0)), "" ) -> 9 | G2: =tbl_Ventes[[#This Row],[Qté Vendue]] * IFERROR(_xlfn.XLOOKUP(tbl_Ventes[[#This Row],[Cde_Prdt]], tbl_Produits[Cde_Prdt], tbl_Produits[Prix Menu]), 0) -> 297 | H2: =IFERROR(_xlfn.XLOOKUP(tbl_Ventes[[#This Row],[Cde_Prdt]], tbl_Produits[Cde_Prdt], tbl_Produits[Coût Moyen Portion]), 0) -> 7 | I2: =tbl_Ventes[[#This Row],[Qté Vendue]] * tbl_Ventes[[#This Row],[CMP_par_portion]] -> 231 | J2: =tbl_Ventes[[#This Row],[CA ligne]] - tbl_Ventes[[#This Row],[Coût matière ligne]] -> 66 | K2: =IFERROR(INDEX(tbl_ProduitsRef[Famille], MATCH(tbl_Ventes[[#This Row],[Cde_Prdt]], tbl_Produits[Cde_Prdt], 0)), "") -> Suppléments
A3: 45956 | B3: =IFERROR(TEXT(tbl_Ventes[[#This Row],[Date]],"mm-aaaa"),"") -> 10-2025 | C3: Espagnol | D3: =IFERROR( INDEX(tbl_ProduitsRef[Cde_Prdt],MATCH(tbl_Ventes[[#This Row],[Produit]],tbl_ProduitsRef[Produit],0)), "" ) -> PDJ005 | E3: 350 | F3: =IFERROR( INDEX(tbl_ProduitsRef[Prix Menu],MATCH(tbl_Ventes[[#This Row],[Produit]],tbl_ProduitsRef[Produit],0)), "" ) -> 54 | G3: =tbl_Ventes[[#This Row],[Qté Vendue]] * IFERROR(_xlfn.XLOOKUP(tbl_Ventes[[#This Row],[Cde_Prdt]], tbl_Produits[Cde_Prdt], tbl_Produits[Prix Menu]), 0) -> 18900 | H3: =IFERROR(_xlfn.XLOOKUP(tbl_Ventes[[#This Row],[Cde_Prdt]], tbl_Produits[Cde_Prdt], tbl_Produits[Coût Moyen Portion]), 0) -> 24.5 | I3: =tbl_Ventes[[#This Row],[Qté Vendue]] * tbl_Ventes[[#This Row],[CMP_par_portion]] -> 8575 | J3: =tbl_Ventes[[#This Row],[CA ligne]] - tbl_Ventes[[#This Row],[Coût matière ligne]] -> 10325 | K3: =IFERROR(INDEX(tbl_ProduitsRef[Famille], MATCH(tbl_Ventes[[#This Row],[Cde_Prdt]], tbl_Produits[Cde_Prdt], 0)), "") -> Petits déjeuners
A4: 45957 | B4: =IFERROR(TEXT(tbl_Ventes[[#This Row],[Date]],"mm-aaaa"),"") -> 10-2025 | C4: Merguez (nature, piquant, normal) | D4: =IFERROR( INDEX(tbl_ProduitsRef[Cde_Prdt],MATCH(tbl_Ventes[[#This Row],[Produit]],tbl_ProduitsRef[Produit],0)), "" ) -> VIA010 | E4: 400 | F4: =IFERROR( INDEX(tbl_ProduitsRef[Prix Menu],MATCH(tbl_Ventes[[#This Row],[Produit]],tbl_ProduitsRef[Produit],0)), "" ) -> 180 | G4: =tbl_Ventes[[#This Row],[Qté Vendue]] * IFERROR(_xlfn.XLOOKUP(tbl_Ventes[[#This Row],[Cde_Prdt]], tbl_Produits[Cde_Prdt], tbl_Produits[Prix Menu]), 0) -> 72000 | H4: =IFERROR(_xlfn.XLOOKUP(tbl_Ventes[[#This Row],[Cde_Prdt]], tbl_Produits[Cde_Prdt], tbl_Produits[Coût Moyen Portion]), 0) -> 200 | I4: =tbl_Ventes[[#This Row],[Qté Vendue]] * tbl_Ventes[[#This Row],[CMP_par_portion]] -> 80000 | J4: =tbl_Ventes[[#This Row],[CA ligne]] - tbl_Ventes[[#This Row],[Coût matière ligne]] -> -8000 | K4: =IFERROR(INDEX(tbl_ProduitsRef[Famille], MATCH(tbl_Ventes[[#This Row],[Cde_Prdt]], tbl_Produits[Cde_Prdt], 0)), "") -> Boucherie
A5: 45958 | B5: =IFERROR(TEXT(tbl_Ventes[[#This Row],[Date]],"mm-aaaa"),"") -> 10-2025 | C5: Marroccino | D5: =IFERROR( INDEX(tbl_ProduitsRef[Cde_Prdt],MATCH(tbl_Ventes[[#This Row],[Produit]],tbl_ProduitsRef[Produit],0)), "" ) -> BCH017 | E5: 51 | F5: =IFERROR( INDEX(tbl_ProduitsRef[Prix Menu],MATCH(tbl_Ventes[[#This Row],[Produit]],tbl_ProduitsRef[Produit],0)), "" ) -> 27 | G5: =tbl_Ventes[[#This Row],[Qté Vendue]] * IFERROR(_xlfn.XLOOKUP(tbl_Ventes[[#This Row],[Cde_Prdt]], tbl_Produits[Cde_Prdt], tbl_Produits[Prix Menu]), 0) -> 1377 | H5: =IFERROR(_xlfn.XLOOKUP(tbl_Ventes[[#This Row],[Cde_Prdt]], tbl_Produits[Cde_Prdt], tbl_Produits[Coût Moyen Portion]), 0) -> 19.36 | I5: =tbl_Ventes[[#This Row],[Qté Vendue]] * tbl_Ventes[[#This Row],[CMP_par_portion]] -> 987.36 | J5: =tbl_Ventes[[#This Row],[CA ligne]] - tbl_Ventes[[#This Row],[Coût matière ligne]] -> 389.64 | K5: =IFERROR(INDEX(tbl_ProduitsRef[Famille], MATCH(tbl_Ventes[[#This Row],[Cde_Prdt]], tbl_Produits[Cde_Prdt], 0)), "") -> Boissons chaudes
A6: 45959 | B6: =IFERROR(TEXT(tbl_Ventes[[#This Row],[Date]],"mm-aaaa"),"") -> 10-2025 | C6: Tajine de poulet beldi (raisins/oignons ) 1/2Kg | D6: =IFERROR( INDEX(tbl_ProduitsRef[Cde_Prdt],MATCH(tbl_Ventes[[#This Row],[Produit]],tbl_ProduitsRef[Produit],0)), "" ) -> TAJ005 | E6: 500 | F6: =IFERROR( INDEX(tbl_ProduitsRef[Prix Menu],MATCH(tbl_Ventes[[#This Row],[Produit]],tbl_ProduitsRef[Produit],0)), "" ) -> 105 | G6: =tbl_Ventes[[#This Row],[Qté Vendue]] * IFERROR(_xlfn.XLOOKUP(tbl_Ventes[[#This Row],[Cde_Prdt]], tbl_Produits[Cde_Prdt], tbl_Produits[Prix Menu]), 0) -> 52500 | H6: =IFERROR(_xlfn.XLOOKUP(tbl_Ventes[[#This Row],[Cde_Prdt]], tbl_Produits[Cde_Prdt], tbl_Produits[Coût Moyen Portion]), 0) -> 35.84 | I6: =tbl_Ventes[[#This Row],[Qté Vendue]] * tbl_Ventes[[#This Row],[CMP_par_portion]] -> 17920 | J6: =tbl_Ventes[[#This Row],[CA ligne]] - tbl_Ventes[[#This Row],[Coût matière ligne]] -> 34580 | K6: =IFERROR(INDEX(tbl_ProduitsRef[Famille], MATCH(tbl_Ventes[[#This Row],[Cde_Prdt]], tbl_Produits[Cde_Prdt], 0)), "") -> Tajines & Coin marocain
A7: 45960 | B7: =IFERROR(TEXT(tbl_Ventes[[#This Row],[Date]],"mm-aaaa"),"") -> 10-2025 | C7: Marroccino | D7: =IFERROR( INDEX(tbl_ProduitsRef[Cde_Prdt],MATCH(tbl_Ventes[[#This Row],[Produit]],tbl_ProduitsRef[Produit],0)), "" ) -> BCH017 | E7: 800 | F7: =IFERROR( INDEX(tbl_ProduitsRef[Prix Menu],MATCH(tbl_Ventes[[#This Row],[Produit]],tbl_ProduitsRef[Produit],0)), "" ) -> 27 | G7: =tbl_Ventes[[#This Row],[Qté Vendue]] * IFERROR(_xlfn.XLOOKUP(tbl_Ventes[[#This Row],[Cde_Prdt]], tbl_Produits[Cde_Prdt], tbl_Produits[Prix Menu]), 0) -> 21600 | H7: =IFERROR(_xlfn.XLOOKUP(tbl_Ventes[[#This Row],[Cde_Prdt]], tbl_Produits[Cde_Prdt], tbl_Produits[Coût Moyen Portion]), 0) -> 19.36 | I7: =tbl_Ventes[[#This Row],[Qté Vendue]] * tbl_Ventes[[#This Row],[CMP_par_portion]] -> 15488 | J7: =tbl_Ventes[[#This Row],[CA ligne]] - tbl_Ventes[[#This Row],[Coût matière ligne]] -> 6112 | K7: =IFERROR(INDEX(tbl_ProduitsRef[Famille], MATCH(tbl_Ventes[[#This Row],[Cde_Prdt]], tbl_Produits[Cde_Prdt], 0)), "") -> Boissons chaudes
A8: 45961 | B8: =IFERROR(TEXT(tbl_Ventes[[#This Row],[Date]],"mm-aaaa"),"") -> 10-2025 | C8: Tajine de poulet beldi (raisins/oignons ) 1/2Kg | D8: =IFERROR( INDEX(tbl_ProduitsRef[Cde_Prdt],MATCH(tbl_Ventes[[#This Row],[Produit]],tbl_ProduitsRef[Produit],0)), "" ) -> TAJ005 | E8: 800 | F8: =IFERROR( INDEX(tbl_ProduitsRef[Prix Menu],MATCH(tbl_Ventes[[#This Row],[Produit]],tbl_ProduitsRef[Produit],0)), "" ) -> 105 | G8: =tbl_Ventes[[#This Row],[Qté Vendue]] * IFERROR(_xlfn.XLOOKUP(tbl_Ventes[[#This Row],[Cde_Prdt]], tbl_Produits[Cde_Prdt], tbl_Produits[Prix Menu]), 0) -> 84000 | H8: =IFERROR(_xlfn.XLOOKUP(tbl_Ventes[[#This Row],[Cde_Prdt]], tbl_Produits[Cde_Prdt], tbl_Produits[Coût Moyen Portion]), 0) -> 35.84 | I8: =tbl_Ventes[[#This Row],[Qté Vendue]] * tbl_Ventes[[#This Row],[CMP_par_portion]] -> 28672 | J8: =tbl_Ventes[[#This Row],[CA ligne]] - tbl_Ventes[[#This Row],[Coût matière ligne]] -> 55328 | K8: =IFERROR(INDEX(tbl_ProduitsRef[Famille], MATCH(tbl_Ventes[[#This Row],[Cde_Prdt]], tbl_Produits[Cde_Prdt], 0)), "") -> Tajines & Coin marocain
A9: 45936 | B9: =IFERROR(TEXT(tbl_Ventes[[#This Row],[Date]],"mm-aaaa"),"") -> 10-2025 | C9: Tajine de poulet beldi (citron confit) 1Kg | D9: =IFERROR( INDEX(tbl_ProduitsRef[Cde_Prdt],MATCH(tbl_Ventes[[#This Row],[Produit]],tbl_ProduitsRef[Produit],0)), "" ) -> TAJ008 | E9: 900 | F9: =IFERROR( INDEX(tbl_ProduitsRef[Prix Menu],MATCH(tbl_Ventes[[#This Row],[Produit]],tbl_ProduitsRef[Produit],0)), "" ) -> 210 | G9: =tbl_Ventes[[#This Row],[Qté Vendue]] * IFERROR(_xlfn.XLOOKUP(tbl_Ventes[[#This Row],[Cde_Prdt]], tbl_Produits[Cde_Prdt], tbl_Produits[Prix Menu]), 0) -> 189000 | H9: =IFERROR(_xlfn.XLOOKUP(tbl_Ventes[[#This Row],[Cde_Prdt]], tbl_Produits[Cde_Prdt], tbl_Produits[Coût Moyen Portion]), 0) -> 73.7 | I9: =tbl_Ventes[[#This Row],[Qté Vendue]] * tbl_Ventes[[#This Row],[CMP_par_portion]] -> 66330 | J9: =tbl_Ventes[[#This Row],[CA ligne]] - tbl_Ventes[[#This Row],[Coût matière ligne]] -> 122670 | K9: =IFERROR(INDEX(tbl_ProduitsRef[Famille], MATCH(tbl_Ventes[[#This Row],[Cde_Prdt]], tbl_Produits[Cde_Prdt], 0)), "") -> Tajines & Coin marocain
A10: 45937 | B10: =IFERROR(TEXT(tbl_Ventes[[#This Row],[Date]],"mm-aaaa"),"") -> 10-2025 | C10: Milkshakes Noisette | D10: =IFERROR( INDEX(tbl_ProduitsRef[Cde_Prdt],MATCH(tbl_Ventes[[#This Row],[Produit]],tbl_ProduitsRef[Produit],0)), "" ) -> MKS006 | E10: 80 | F10: =IFERROR( INDEX(tbl_ProduitsRef[Prix Menu],MATCH(tbl_Ventes[[#This Row],[Produit]],tbl_ProduitsRef[Produit],0)), "" ) -> 35 | G10: =tbl_Ventes[[#This Row],[Qté Vendue]] * IFERROR(_xlfn.XLOOKUP(tbl_Ventes[[#This Row],[Cde_Prdt]], tbl_Produits[Cde_Prdt], tbl_Produits[Prix Menu]), 0) -> 2800 | H10: =IFERROR(_xlfn.XLOOKUP(tbl_Ventes[[#This Row],[Cde_Prdt]], tbl_Produits[Cde_Prdt], tbl_Produits[Coût Moyen Portion]), 0) -> 17.3 | I10: =tbl_Ventes[[#This Row],[Qté Vendue]] * tbl_Ventes[[#This Row],[CMP_par_portion]] -> 1384 | J10: =tbl_Ventes[[#This Row],[CA ligne]] - tbl_Ventes[[#This Row],[Coût matière ligne]] -> 1416 | K10: =IFERROR(INDEX(tbl_ProduitsRef[Famille], MATCH(tbl_Ventes[[#This Row],[Cde_Prdt]], tbl_Produits[Cde_Prdt], 0)), "") -> Milkshakes
A11: 45938 | B11: =IFERROR(TEXT(tbl_Ventes[[#This Row],[Date]],"mm-aaaa"),"") -> 10-2025 | C11: Merguez (nature, piquant, normal) | D11: =IFERROR( INDEX(tbl_ProduitsRef[Cde_Prdt],MATCH(tbl_Ventes[[#This Row],[Produit]],tbl_ProduitsRef[Produit],0)), "" ) -> VIA010 | E11: 150 | F11: =IFERROR( INDEX(tbl_ProduitsRef[Prix Menu],MATCH(tbl_Ventes[[#This Row],[Produit]],tbl_ProduitsRef[Produit],0)), "" ) -> 180 | G11: =tbl_Ventes[[#This Row],[Qté Vendue]] * IFERROR(_xlfn.XLOOKUP(tbl_Ventes[[#This Row],[Cde_Prdt]], tbl_Produits[Cde_Prdt], tbl_Produits[Prix Menu]), 0) -> 27000 | H11: =IFERROR(_xlfn.XLOOKUP(tbl_Ventes[[#This Row],[Cde_Prdt]], tbl_Produits[Cde_Prdt], tbl_Produits[Coût Moyen Portion]), 0) -> 200 | I11: =tbl_Ventes[[#This Row],[Qté Vendue]] * tbl_Ventes[[#This Row],[CMP_par_portion]] -> 30000 | J11: =tbl_Ventes[[#This Row],[CA ligne]] - tbl_Ventes[[#This Row],[Coût matière ligne]] -> -3000 | K11: =IFERROR(INDEX(tbl_ProduitsRef[Famille], MATCH(tbl_Ventes[[#This Row],[Cde_Prdt]], tbl_Produits[Cde_Prdt], 0)), "") -> Boucherie
A12: 45939 | B12: =IFERROR(TEXT(tbl_Ventes[[#This Row],[Date]],"mm-aaaa"),"") -> 10-2025 | C12: Entrecôte de veau | D12: =IFERROR( INDEX(tbl_ProduitsRef[Cde_Prdt],MATCH(tbl_Ventes[[#This Row],[Produit]],tbl_ProduitsRef[Produit],0)), "" ) -> VIA006 | E12: 50 | F12: =IFERROR( INDEX(tbl_ProduitsRef[Prix Menu],MATCH(tbl_Ventes[[#This Row],[Produit]],tbl_ProduitsRef[Produit],0)), "" ) -> 190 | G12: =tbl_Ventes[[#This Row],[Qté Vendue]] * IFERROR(_xlfn.XLOOKUP(tbl_Ventes[[#This Row],[Cde_Prdt]], tbl_Produits[Cde_Prdt], tbl_Produits[Prix Menu]), 0) -> 9500 | H12: =IFERROR(_xlfn.XLOOKUP(tbl_Ventes[[#This Row],[Cde_Prdt]], tbl_Produits[Cde_Prdt], tbl_Produits[Coût Moyen Portion]), 0) -> 300 | I12: =tbl_Ventes[[#This Row],[Qté Vendue]] * tbl_Ventes[[#This Row],[CMP_par_portion]] -> 15000 | J12: =tbl_Ventes[[#This Row],[CA ligne]] - tbl_Ventes[[#This Row],[Coût matière ligne]] -> -5500 | K12: =IFERROR(INDEX(tbl_ProduitsRef[Famille], MATCH(tbl_Ventes[[#This Row],[Cde_Prdt]], tbl_Produits[Cde_Prdt], 0)), "") -> Boucherie
A13: 45940 | B13: =IFERROR(TEXT(tbl_Ventes[[#This Row],[Date]],"mm-aaaa"),"") -> 10-2025 | C13: Viennoiserie G | D13: =IFERROR( INDEX(tbl_ProduitsRef[Cde_Prdt],MATCH(tbl_Ventes[[#This Row],[Produit]],tbl_ProduitsRef[Produit],0)), "" ) -> SUP005 | E13: 88 | F13: =IFERROR( INDEX(tbl_ProduitsRef[Prix Menu],MATCH(tbl_Ventes[[#This Row],[Produit]],tbl_ProduitsRef[Produit],0)), "" ) -> 9 | G13: =tbl_Ventes[[#This Row],[Qté Vendue]] * IFERROR(_xlfn.XLOOKUP(tbl_Ventes[[#This Row],[Cde_Prdt]], tbl_Produits[Cde_Prdt], tbl_Produits[Prix Menu]), 0) -> 792 | H13: =IFERROR(_xlfn.XLOOKUP(tbl_Ventes[[#This Row],[Cde_Prdt]], tbl_Produits[Cde_Prdt], tbl_Produits[Coût Moyen Portion]), 0) -> 7 | I13: =tbl_Ventes[[#This Row],[Qté Vendue]] * tbl_Ventes[[#This Row],[CMP_par_portion]] -> 616 | J13: =tbl_Ventes[[#This Row],[CA ligne]] - tbl_Ventes[[#This Row],[Coût matière ligne]] -> 176 | K13: =IFERROR(INDEX(tbl_ProduitsRef[Famille], MATCH(tbl_Ventes[[#This Row],[Cde_Prdt]], tbl_Produits[Cde_Prdt], 0)), "") -> Suppléments
... A16: 45943 | B16: =IFERROR(TEXT(tbl_Ventes[[#This Row],[Date]],"mm-aaaa"),"") -> 10-2025 | C16: Marroccino | D16: =IFERROR( INDEX(tbl_ProduitsRef[Cde_Prdt],MATCH(tbl_Ventes[[#This Row],[Produit]],tbl_ProduitsRef[Produit],0)), "" ) -> BCH017 | E16: 10 | F16: =IFERROR( INDEX(tbl_ProduitsRef[Prix Menu],MATCH(tbl_Ventes[[#This Row],[Produit]],tbl_ProduitsRef[Produit],0)), "" ) -> 27 | G16: =tbl_Ventes[[#This Row],[Qté Vendue]] * IFERROR(_xlfn.XLOOKUP(tbl_Ventes[[#This Row],[Cde_Prdt]], tbl_Produits[Cde_Prdt], tbl_Produits[Prix Menu]), 0) -> 270 | H16: =IFERROR(_xlfn.XLOOKUP(tbl_Ventes[[#This Row],[Cde_Prdt]], tbl_Produits[Cde_Prdt], tbl_Produits[Coût Moyen Portion]), 0) -> 19.36 | I16: =tbl_Ventes[[#This Row],[Qté Vendue]] * tbl_Ventes[[#This Row],[CMP_par_portion]] -> 193.6 | J16: =tbl_Ventes[[#This Row],[CA ligne]] - tbl_Ventes[[#This Row],[Coût matière ligne]] -> 76.4 | K16: =IFERROR(INDEX(tbl_ProduitsRef[Famille], MATCH(tbl_Ventes[[#This Row],[Cde_Prdt]], tbl_Produits[Cde_Prdt], 0)), "") -> Boissons chaudes
A17: 45944 | B17: =IFERROR(TEXT(tbl_Ventes[[#This Row],[Date]],"mm-aaaa"),"") -> 10-2025 | C17: Tajine de poulet beldi (raisins/oignons ) 1/2Kg | D17: =IFERROR( INDEX(tbl_ProduitsRef[Cde_Prdt],MATCH(tbl_Ventes[[#This Row],[Produit]],tbl_ProduitsRef[Produit],0)), "" ) -> TAJ005 | E17: 20 | F17: =IFERROR( INDEX(tbl_ProduitsRef[Prix Menu],MATCH(tbl_Ventes[[#This Row],[Produit]],tbl_ProduitsRef[Produit],0)), "" ) -> 105 | G17: =tbl_Ventes[[#This Row],[Qté Vendue]] * IFERROR(_xlfn.XLOOKUP(tbl_Ventes[[#This Row],[Cde_Prdt]], tbl_Produits[Cde_Prdt], tbl_Produits[Prix Menu]), 0) -> 2100 | H17: =IFERROR(_xlfn.XLOOKUP(tbl_Ventes[[#This Row],[Cde_Prdt]], tbl_Produits[Cde_Prdt], tbl_Produits[Coût Moyen Portion]), 0) -> 35.84 | I17: =tbl_Ventes[[#This Row],[Qté Vendue]] * tbl_Ventes[[#This Row],[CMP_par_portion]] -> 716.8 | J17: =tbl_Ventes[[#This Row],[CA ligne]] - tbl_Ventes[[#This Row],[Coût matière ligne]] -> 1383.2 | K17: =IFERROR(INDEX(tbl_ProduitsRef[Famille], MATCH(tbl_Ventes[[#This Row],[Cde_Prdt]], tbl_Produits[Cde_Prdt], 0)), "") -> Tajines & Coin marocain | O17: Ca Journalier
A18: 45945 | B18: =IFERROR(TEXT(tbl_Ventes[[#This Row],[Date]],"mm-aaaa"),"") -> 10-2025 | C18: Marroccino | D18: =IFERROR( INDEX(tbl_ProduitsRef[Cde_Prdt],MATCH(tbl_Ventes[[#This Row],[Produit]],tbl_ProduitsRef[Produit],0)), "" ) -> BCH017 | E18: 33 | F18: =IFERROR( INDEX(tbl_ProduitsRef[Prix Menu],MATCH(tbl_Ventes[[#This Row],[Produit]],tbl_ProduitsRef[Produit],0)), "" ) -> 27 | G18: =tbl_Ventes[[#This Row],[Qté Vendue]] * IFERROR(_xlfn.XLOOKUP(tbl_Ventes[[#This Row],[Cde_Prdt]], tbl_Produits[Cde_Prdt], tbl_Produits[Prix Menu]), 0) -> 891 | H18: =IFERROR(_xlfn.XLOOKUP(tbl_Ventes[[#This Row],[Cde_Prdt]], tbl_Produits[Cde_Prdt], tbl_Produits[Coût Moyen Portion]), 0) -> 19.36 | I18: =tbl_Ventes[[#This Row],[Qté Vendue]] * tbl_Ventes[[#This Row],[CMP_par_portion]] -> 638.88 | J18: =tbl_Ventes[[#This Row],[CA ligne]] - tbl_Ventes[[#This Row],[Coût matière ligne]] -> 252.12 | K18: =IFERROR(INDEX(tbl_ProduitsRef[Famille], MATCH(tbl_Ventes[[#This Row],[Cde_Prdt]], tbl_Produits[Cde_Prdt], 0)), "") -> Boissons chaudes | O18: =SUMIFS(tbl_Ventes[CA ligne],tbl_Ventes[Date],A2) -> 2922
A19: 45946 | B19: =IFERROR(TEXT(tbl_Ventes[[#This Row],[Date]],"mm-aaaa"),"") -> 10-2025 | C19: Tajine de poulet beldi (raisins/oignons ) 1/2Kg | D19: =IFERROR( INDEX(tbl_ProduitsRef[Cde_Prdt],MATCH(tbl_Ventes[[#This Row],[Produit]],tbl_ProduitsRef[Produit],0)), "" ) -> TAJ005 | E19: 25 | F19: =IFERROR( INDEX(tbl_ProduitsRef[Prix Menu],MATCH(tbl_Ventes[[#This Row],[Produit]],tbl_ProduitsRef[Produit],0)), "" ) -> 105 | G19: =tbl_Ventes[[#This Row],[Qté Vendue]] * IFERROR(_xlfn.XLOOKUP(tbl_Ventes[[#This Row],[Cde_Prdt]], tbl_Produits[Cde_Prdt], tbl_Produits[Prix Menu]), 0) -> 2625 | H19: =IFERROR(_xlfn.XLOOKUP(tbl_Ventes[[#This Row],[Cde_Prdt]], tbl_Produits[Cde_Prdt], tbl_Produits[Coût Moyen Portion]), 0) -> 35.84 | I19: =tbl_Ventes[[#This Row],[Qté Vendue]] * tbl_Ventes[[#This Row],[CMP_par_portion]] -> 896 | J19: =tbl_Ventes[[#This Row],[CA ligne]] - tbl_Ventes[[#This Row],[Coût matière ligne]] -> 1729 | K19: =IFERROR(INDEX(tbl_ProduitsRef[Famille], MATCH(tbl_Ventes[[#This Row],[Cde_Prdt]], tbl_Produits[Cde_Prdt], 0)), "") -> Tajines & Coin marocain | O19: CA Mansuel
A20: 45947 | B20: =IFERROR(TEXT(tbl_Ventes[[#This Row],[Date]],"mm-aaaa"),"") -> 10-2025 | C20: Tajine de poulet beldi (citron confit) 1Kg | D20: =IFERROR( INDEX(tbl_ProduitsRef[Cde_Prdt],MATCH(tbl_Ventes[[#This Row],[Produit]],tbl_ProduitsRef[Produit],0)), "" ) -> TAJ008 | E20: 150 | F20: =IFERROR( INDEX(tbl_ProduitsRef[Prix Menu],MATCH(tbl_Ventes[[#This Row],[Produit]],tbl_ProduitsRef[Produit],0)), "" ) -> 210 | G20: =tbl_Ventes[[#This Row],[Qté Vendue]] * IFERROR(_xlfn.XLOOKUP(tbl_Ventes[[#This Row],[Cde_Prdt]], tbl_Produits[Cde_Prdt], tbl_Produits[Prix Menu]), 0) -> 31500 | H20: =IFERROR(_xlfn.XLOOKUP(tbl_Ventes[[#This Row],[Cde_Prdt]], tbl_Produits[Cde_Prdt], tbl_Produits[Coût Moyen Portion]), 0) -> 73.7 | I20: =tbl_Ventes[[#This Row],[Qté Vendue]] * tbl_Ventes[[#This Row],[CMP_par_portion]] -> 11055 | J20: =tbl_Ventes[[#This Row],[CA ligne]] - tbl_Ventes[[#This Row],[Coût matière ligne]] -> 20445 | K20: =IFERROR(INDEX(tbl_ProduitsRef[Famille], MATCH(tbl_Ventes[[#This Row],[Cde_Prdt]], tbl_Produits[Cde_Prdt], 0)), "") -> Tajines & Coin marocain | O20: =SUMIFS(tbl_Ventes[CA ligne],tbl_Ventes[Mois],"2025-12") -> 0
A21: 45948 | B21: =IFERROR(TEXT(tbl_Ventes[[#This Row],[Date]],"mm-aaaa"),"") -> 10-2025 | C21: Milkshakes Noisette | D21: =IFERROR( INDEX(tbl_ProduitsRef[Cde_Prdt],MATCH(tbl_Ventes[[#This Row],[Produit]],tbl_ProduitsRef[Produit],0)), "" ) -> MKS006 | E21: 30 | F21: =IFERROR( INDEX(tbl_ProduitsRef[Prix Menu],MATCH(tbl_Ventes[[#This Row],[Produit]],tbl_ProduitsRef[Produit],0)), "" ) -> 35 | G21: =tbl_Ventes[[#This Row],[Qté Vendue]] * IFERROR(_xlfn.XLOOKUP(tbl_Ventes[[#This Row],[Cde_Prdt]], tbl_Produits[Cde_Prdt], tbl_Produits[Prix Menu]), 0) -> 1050 | H21: =IFERROR(_xlfn.XLOOKUP(tbl_Ventes[[#This Row],[Cde_Prdt]], tbl_Produits[Cde_Prdt], tbl_Produits[Coût Moyen Portion]), 0) -> 17.3 | I21: =tbl_Ventes[[#This Row],[Qté Vendue]] * tbl_Ventes[[#This Row],[CMP_par_portion]] -> 519 | J21: =tbl_Ventes[[#This Row],[CA ligne]] - tbl_Ventes[[#This Row],[Coût matière ligne]] -> 531 | K21: =IFERROR(INDEX(tbl_ProduitsRef[Famille], MATCH(tbl_Ventes[[#This Row],[Cde_Prdt]], tbl_Produits[Cde_Prdt], 0)), "") -> Milkshakes
A22: 45949 | B22: =IFERROR(TEXT(tbl_Ventes[[#This Row],[Date]],"mm-aaaa"),"") -> 10-2025 | C22: Merguez (nature, piquant, normal) | D22: =IFERROR( INDEX(tbl_ProduitsRef[Cde_Prdt],MATCH(tbl_Ventes[[#This Row],[Produit]],tbl_ProduitsRef[Produit],0)), "" ) -> VIA010 | E22: 78 | F22: =IFERROR( INDEX(tbl_ProduitsRef[Prix Menu],MATCH(tbl_Ventes[[#This Row],[Produit]],tbl_ProduitsRef[Produit],0)), "" ) -> 180 | G22: =tbl_Ventes[[#This Row],[Qté Vendue]] * IFERROR(_xlfn.XLOOKUP(tbl_Ventes[[#This Row],[Cde_Prdt]], tbl_Produits[Cde_Prdt], tbl_Produits[Prix Menu]), 0) -> 14040 | H22: =IFERROR(_xlfn.XLOOKUP(tbl_Ventes[[#This Row],[Cde_Prdt]], tbl_Produits[Cde_Prdt], tbl_Produits[Coût Moyen Portion]), 0) -> 200 | I22: =tbl_Ventes[[#This Row],[Qté Vendue]] * tbl_Ventes[[#This Row],[CMP_par_portion]] -> 15600 | J22: =tbl_Ventes[[#This Row],[CA ligne]] - tbl_Ventes[[#This Row],[Coût matière ligne]] -> -1560 | K22: =IFERROR(INDEX(tbl_ProduitsRef[Famille], MATCH(tbl_Ventes[[#This Row],[Cde_Prdt]], tbl_Produits[Cde_Prdt], 0)), "") -> Boucherie
A23: 45950 | B23: =IFERROR(TEXT(tbl_Ventes[[#This Row],[Date]],"mm-aaaa"),"") -> 10-2025 | C23: Omelette aux crevettes | D23: =IFERROR( INDEX(tbl_ProduitsRef[Cde_Prdt],MATCH(tbl_Ventes[[#This Row],[Produit]],tbl_ProduitsRef[Produit],0)), "" ) -> OME001 | E23: 69 | F23: =IFERROR( INDEX(tbl_ProduitsRef[Prix Menu],MATCH(tbl_Ventes[[#This Row],[Produit]],tbl_ProduitsRef[Produit],0)), "" ) -> 35 | G23: =tbl_Ventes[[#This Row],[Qté Vendue]] * IFERROR(_xlfn.XLOOKUP(tbl_Ventes[[#This Row],[Cde_Prdt]], tbl_Produits[Cde_Prdt], tbl_Produits[Prix Menu]), 0) -> 2415 | H23: =IFERROR(_xlfn.XLOOKUP(tbl_Ventes[[#This Row],[Cde_Prdt]], tbl_Produits[Cde_Prdt], tbl_Produits[Coût Moyen Portion]), 0) -> 9.09 | I23: =tbl_Ventes[[#This Row],[Qté Vendue]] * tbl_Ventes[[#This Row],[CMP_par_portion]] -> 627.21 | J23: =tbl_Ventes[[#This Row],[CA ligne]] - tbl_Ventes[[#This Row],[Coût matière ligne]] -> 1787.79 | K23: =IFERROR(INDEX(tbl_ProduitsRef[Famille], MATCH(tbl_Ventes[[#This Row],[Cde_Prdt]], tbl_Produits[Cde_Prdt], 0)), "") -> Œufs & Omelettes
A24: 45951 | B24: =IFERROR(TEXT(tbl_Ventes[[#This Row],[Date]],"mm-aaaa"),"") -> 10-2025 | C24: Omelette maison | D24: =IFERROR( INDEX(tbl_ProduitsRef[Cde_Prdt],MATCH(tbl_Ventes[[#This Row],[Produit]],tbl_ProduitsRef[Produit],0)), "" ) -> OME003 | E24: 33 | F24: =IFERROR( INDEX(tbl_ProduitsRef[Prix Menu],MATCH(tbl_Ventes[[#This Row],[Produit]],tbl_ProduitsRef[Produit],0)), "" ) -> 22 | G24: =tbl_Ventes[[#This Row],[Qté Vendue]] * IFERROR(_xlfn.XLOOKUP(tbl_Ventes[[#This Row],[Cde_Prdt]], tbl_Produits[Cde_Prdt], tbl_Produits[Prix Menu]), 0) -> 726 | H24: =IFERROR(_xlfn.XLOOKUP(tbl_Ventes[[#This Row],[Cde_Prdt]], tbl_Produits[Cde_Prdt], tbl_Produits[Coût Moyen Portion]), 0) -> 20.81 | I24: =tbl_Ventes[[#This Row],[Qté Vendue]] * tbl_Ventes[[#This Row],[CMP_par_portion]] -> 686.73 | J24: =tbl_Ventes[[#This Row],[CA ligne]] - tbl_Ventes[[#This Row],[Coût matière ligne]] -> 39.27 | K24: =IFERROR(INDEX(tbl_ProduitsRef[Famille], MATCH(tbl_Ventes[[#This Row],[Cde_Prdt]], tbl_Produits[Cde_Prdt], 0)), "") -> Œufs & Omelettes
A25: 45952 | B25: =IFERROR(TEXT(tbl_Ventes[[#This Row],[Date]],"mm-aaaa"),"") -> 10-2025 | C25: Omelette végétarienne | D25: =IFERROR( INDEX(tbl_ProduitsRef[Cde_Prdt],MATCH(tbl_Ventes[[#This Row],[Produit]],tbl_ProduitsRef[Produit],0)), "" ) -> OME004 | E25: 12 | F25: =IFERROR( INDEX(tbl_ProduitsRef[Prix Menu],MATCH(tbl_Ventes[[#This Row],[Produit]],tbl_ProduitsRef[Produit],0)), "" ) -> 20 | G25: =tbl_Ventes[[#This Row],[Qté Vendue]] * IFERROR(_xlfn.XLOOKUP(tbl_Ventes[[#This Row],[Cde_Prdt]], tbl_Produits[Cde_Prdt], tbl_Produits[Prix Menu]), 0) -> 240 | H25: =IFERROR(_xlfn.XLOOKUP(tbl_Ventes[[#This Row],[Cde_Prdt]], tbl_Produits[Cde_Prdt], tbl_Produits[Coût Moyen Portion]), 0) -> 13.49 | I25: =tbl_Ventes[[#This Row],[Qté Vendue]] * tbl_Ventes[[#This Row],[CMP_par_portion]] -> 161.88 | J25: =tbl_Ventes[[#This Row],[CA ligne]] - tbl_Ventes[[#This Row],[Coût matière ligne]] -> 78.12 | K25: =IFERROR(INDEX(tbl_ProduitsRef[Famille], MATCH(tbl_Ventes[[#This Row],[Cde_Prdt]], tbl_Produits[Cde_Prdt], 0)), "") -> Œufs & Omelettes
A26: 45953 | B26: =IFERROR(TEXT(tbl_Ventes[[#This Row],[Date]],"mm-aaaa"),"") -> 10-2025 | C26: Omelette au fromage | D26: =IFERROR( INDEX(tbl_ProduitsRef[Cde_Prdt],MATCH(tbl_Ventes[[#This Row],[Produit]],tbl_ProduitsRef[Produit],0)), "" ) -> OME006 | E26: 11 | F26: =IFERROR( INDEX(tbl_ProduitsRef[Prix Menu],MATCH(tbl_Ventes[[#This Row],[Produit]],tbl_ProduitsRef[Produit],0)), "" ) -> 15 | G26: =tbl_Ventes[[#This Row],[Qté Vendue]] * IFERROR(_xlfn.XLOOKUP(tbl_Ventes[[#This Row],[Cde_Prdt]], tbl_Produits[Cde_Prdt], tbl_Produits[Prix Menu]), 0) -> 165 | H26: =IFERROR(_xlfn.XLOOKUP(tbl_Ventes[[#This Row],[Cde_Prdt]], tbl_Produits[Cde_Prdt], tbl_Produits[Coût Moyen Portion]), 0) -> 12.79 | I26: =tbl_Ventes[[#This Row],[Qté Vendue]] * tbl_Ventes[[#This Row],[CMP_par_portion]] -> 140.69 | J26: =tbl_Ventes[[#This Row],[CA ligne]] - tbl_Ventes[[#This Row],[Coût matière ligne]] -> 24.31 | K26: =IFERROR(INDEX(tbl_ProduitsRef[Famille], MATCH(tbl_Ventes[[#This Row],[Cde_Prdt]], tbl_Produits[Cde_Prdt], 0)), "") -> Œufs & Omelettes
A27: 45954 | B27: =IFERROR(TEXT(tbl_Ventes[[#This Row],[Date]],"mm-aaaa"),"") -> 10-2025 | C27: Marroccino | D27: =IFERROR( INDEX(tbl_ProduitsRef[Cde_Prdt],MATCH(tbl_Ventes[[#This Row],[Produit]],tbl_ProduitsRef[Produit],0)), "" ) -> BCH017 | E27: 10 | F27: =IFERROR( INDEX(tbl_ProduitsRef[Prix Menu],MATCH(tbl_Ventes[[#This Row],[Produit]],tbl_ProduitsRef[Produit],0)), "" ) -> 27 | G27: =tbl_Ventes[[#This Row],[Qté Vendue]] * IFERROR(_xlfn.XLOOKUP(tbl_Ventes[[#This Row],[Cde_Prdt]], tbl_Produits[Cde_Prdt], tbl_Produits[Prix Menu]), 0) -> 270 | H27: =IFERROR(_xlfn.XLOOKUP(tbl_Ventes[[#This Row],[Cde_Prdt]], tbl_Produits[Cde_Prdt], tbl_Produits[Coût Moyen Portion]), 0) -> 19.36 | I27: =tbl_Ventes[[#This Row],[Qté Vendue]] * tbl_Ventes[[#This Row],[CMP_par_portion]] -> 193.6 | J27: =tbl_Ventes[[#This Row],[CA ligne]] - tbl_Ventes[[#This Row],[Coût matière ligne]] -> 76.4 | K27: =IFERROR(INDEX(tbl_ProduitsRef[Famille], MATCH(tbl_Ventes[[#This Row],[Cde_Prdt]], tbl_Produits[Cde_Prdt], 0)), "") -> Boissons chaudes
A28: 45955 | B28: =IFERROR(TEXT(tbl_Ventes[[#This Row],[Date]],"mm-aaaa"),"") -> 10-2025 | C28: Tajine de poulet beldi (raisins/oignons ) 1/2Kg | D28: =IFERROR( INDEX(tbl_ProduitsRef[Cde_Prdt],MATCH(tbl_Ventes[[#This Row],[Produit]],tbl_ProduitsRef[Produit],0)), "" ) -> TAJ005 | E28: 25 | F28: =IFERROR( INDEX(tbl_ProduitsRef[Prix Menu],MATCH(tbl_Ventes[[#This Row],[Produit]],tbl_ProduitsRef[Produit],0)), "" ) -> 105 | G28: =tbl_Ventes[[#This Row],[Qté Vendue]] * IFERROR(_xlfn.XLOOKUP(tbl_Ventes[[#This Row],[Cde_Prdt]], tbl_Produits[Cde_Prdt], tbl_Produits[Prix Menu]), 0) -> 2625 | H28: =IFERROR(_xlfn.XLOOKUP(tbl_Ventes[[#This Row],[Cde_Prdt]], tbl_Produits[Cde_Prdt], tbl_Produits[Coût Moyen Portion]), 0) -> 35.84 | I28: =tbl_Ventes[[#This Row],[Qté Vendue]] * tbl_Ventes[[#This Row],[CMP_par_portion]] -> 896 | J28: =tbl_Ventes[[#This Row],[CA ligne]] - tbl_Ventes[[#This Row],[Coût matière ligne]] -> 1729 | K28: =IFERROR(INDEX(tbl_ProduitsRef[Famille], MATCH(tbl_Ventes[[#This Row],[Cde_Prdt]], tbl_Produits[Cde_Prdt], 0)), "") -> Tajines & Coin marocain
A29: 45956 | B29: =IFERROR(TEXT(tbl_Ventes[[#This Row],[Date]],"mm-aaaa"),"") -> 10-2025 | C29: Marroccino | D29: =IFERROR( INDEX(tbl_ProduitsRef[Cde_Prdt],MATCH(tbl_Ventes[[#This Row],[Produit]],tbl_ProduitsRef[Produit],0)), "" ) -> BCH017 | E29: 30 | F29: =IFERROR( INDEX(tbl_ProduitsRef[Prix Menu],MATCH(tbl_Ventes[[#This Row],[Produit]],tbl_ProduitsRef[Produit],0)), "" ) -> 27 | G29: =tbl_Ventes[[#This Row],[Qté Vendue]] * IFERROR(_xlfn.XLOOKUP(tbl_Ventes[[#This Row],[Cde_Prdt]], tbl_Produits[Cde_Prdt], tbl_Produits[Prix Menu]), 0) -> 810 | H29: =IFERROR(_xlfn.XLOOKUP(tbl_Ventes[[#This Row],[Cde_Prdt]], tbl_Produits[Cde_Prdt], tbl_Produits[Coût Moyen Portion]), 0) -> 19.36 | I29: =tbl_Ventes[[#This Row],[Qté Vendue]] * tbl_Ventes[[#This Row],[CMP_par_portion]] -> 580.8 | J29: =tbl_Ventes[[#This Row],[CA ligne]] - tbl_Ventes[[#This Row],[Coût matière ligne]] -> 229.2 | K29: =IFERROR(INDEX(tbl_ProduitsRef[Famille], MATCH(tbl_Ventes[[#This Row],[Cde_Prdt]], tbl_Produits[Cde_Prdt], 0)), "") -> Boissons chaudes
A30: 45957 | B30: =IFERROR(TEXT(tbl_Ventes[[#This Row],[Date]],"mm-aaaa"),"") -> 10-2025 | C30: Tajine de poulet beldi (raisins/oignons ) 1/2Kg | D30: =IFERROR( INDEX(tbl_ProduitsRef[Cde_Prdt],MATCH(tbl_Ventes[[#This Row],[Produit]],tbl_ProduitsRef[Produit],0)), "" ) -> TAJ005 | E30: 50 | F30: =IFERROR( INDEX(tbl_ProduitsRef[Prix Menu],MATCH(tbl_Ventes[[#This Row],[Produit]],tbl_ProduitsRef[Produit],0)), "" ) -> 105 | G30: =tbl_Ventes[[#This Row],[Qté Vendue]] * IFERROR(_xlfn.XLOOKUP(tbl_Ventes[[#This Row],[Cde_Prdt]], tbl_Produits[Cde_Prdt], tbl_Produits[Prix Menu]), 0) -> 5250 | H30: =IFERROR(_xlfn.XLOOKUP(tbl_Ventes[[#This Row],[Cde_Prdt]], tbl_Produits[Cde_Prdt], tbl_Produits[Coût Moyen Portion]), 0) -> 35.84 | I30: =tbl_Ventes[[#This Row],[Qté Vendue]] * tbl_Ventes[[#This Row],[CMP_par_portion]] -> 1792 | J30: =tbl_Ventes[[#This Row],[CA ligne]] - tbl_Ventes[[#This Row],[Coût matière ligne]] -> 3458 | K30: =IFERROR(INDEX(tbl_ProduitsRef[Famille], MATCH(tbl_Ventes[[#This Row],[Cde_Prdt]], tbl_Produits[Cde_Prdt], 0)), "") -> Tajines & Coin marocain
A31: 45958 | B31: =IFERROR(TEXT(tbl_Ventes[[#This Row],[Date]],"mm-aaaa"),"") -> 10-2025 | C31: Tajine de poulet beldi (citron confit) 1Kg | D31: =IFERROR( INDEX(tbl_ProduitsRef[Cde_Prdt],MATCH(tbl_Ventes[[#This Row],[Produit]],tbl_ProduitsRef[Produit],0)), "" ) -> TAJ008 | E31: 17 | F31: =IFERROR( INDEX(tbl_ProduitsRef[Prix Menu],MATCH(tbl_Ventes[[#This Row],[Produit]],tbl_ProduitsRef[Produit],0)), "" ) -> 210 | G31: =tbl_Ventes[[#This Row],[Qté Vendue]] * IFERROR(_xlfn.XLOOKUP(tbl_Ventes[[#This Row],[Cde_Prdt]], tbl_Produits[Cde_Prdt], tbl_Produits[Prix Menu]), 0) -> 3570 | H31: =IFERROR(_xlfn.XLOOKUP(tbl_Ventes[[#This Row],[Cde_Prdt]], tbl_Produits[Cde_Prdt], tbl_Produits[Coût Moyen Portion]), 0) -> 73.7 | I31: =tbl_Ventes[[#This Row],[Qté Vendue]] * tbl_Ventes[[#This Row],[CMP_par_portion]] -> 1252.9 | J31: =tbl_Ventes[[#This Row],[CA ligne]] - tbl_Ventes[[#This Row],[Coût matière ligne]] -> 2317.1 | K31: =IFERROR(INDEX(tbl_ProduitsRef[Famille], MATCH(tbl_Ventes[[#This Row],[Cde_Prdt]], tbl_Produits[Cde_Prdt], 0)), "") -> Tajines & Coin marocain
A32: 45959 | B32: =IFERROR(TEXT(tbl_Ventes[[#This Row],[Date]],"mm-aaaa"),"") -> 10-2025 | C32: Milkshakes Noisette | D32: =IFERROR( INDEX(tbl_ProduitsRef[Cde_Prdt],MATCH(tbl_Ventes[[#This Row],[Produit]],tbl_ProduitsRef[Produit],0)), "" ) -> MKS006 | E32: 90 | F32: =IFERROR( INDEX(tbl_ProduitsRef[Prix Menu],MATCH(tbl_Ventes[[#This Row],[Produit]],tbl_ProduitsRef[Produit],0)), "" ) -> 35 | G32: =tbl_Ventes[[#This Row],[Qté Vendue]] * IFERROR(_xlfn.XLOOKUP(tbl_Ventes[[#This Row],[Cde_Prdt]], tbl_Produits[Cde_Prdt], tbl_Produits[Prix Menu]), 0) -> 3150 | H32: =IFERROR(_xlfn.XLOOKUP(tbl_Ventes[[#This Row],[Cde_Prdt]], tbl_Produits[Cde_Prdt], tbl_Produits[Coût Moyen Portion]), 0) -> 17.3 | I32: =tbl_Ventes[[#This Row],[Qté Vendue]] * tbl_Ventes[[#This Row],[CMP_par_portion]] -> 1557 | J32: =tbl_Ventes[[#This Row],[CA ligne]] - tbl_Ventes[[#This Row],[Coût matière ligne]] -> 1593 | K32: =IFERROR(INDEX(tbl_ProduitsRef[Famille], MATCH(tbl_Ventes[[#This Row],[Cde_Prdt]], tbl_Produits[Cde_Prdt], 0)), "") -> Milkshakes
... A70: 46016 | B70: =IFERROR(TEXT(tbl_Ventes[[#This Row],[Date]],"mm-aaaa"),"") -> 12-2025 | C70: Amlou amande | D70: =IFERROR( INDEX(tbl_ProduitsRef[Cde_Prdt],MATCH(tbl_Ventes[[#This Row],[Produit]],tbl_ProduitsRef[Produit],0)), "" ) -> SUP002 | E70: 150 | F70: =IFERROR( INDEX(tbl_ProduitsRef[Prix Menu],MATCH(tbl_Ventes[[#This Row],[Produit]],tbl_ProduitsRef[Produit],0)), "" ) -> 12 | G70: =tbl_Ventes[[#This Row],[Qté Vendue]] * IFERROR(_xlfn.XLOOKUP(tbl_Ventes[[#This Row],[Cde_Prdt]], tbl_Produits[Cde_Prdt], tbl_Produits[Prix Menu]), 0) -> 1800 | H70: =IFERROR(_xlfn.XLOOKUP(tbl_Ventes[[#This Row],[Cde_Prdt]], tbl_Produits[Cde_Prdt], tbl_Produits[Coût Moyen Portion]), 0) -> 60 | I70: =tbl_Ventes[[#This Row],[Qté Vendue]] * tbl_Ventes[[#This Row],[CMP_par_portion]] -> 9000 | J70: =tbl_Ventes[[#This Row],[CA ligne]] - tbl_Ventes[[#This Row],[Coût matière ligne]] -> -7200 | K70: =IFERROR(INDEX(tbl_ProduitsRef[Famille], MATCH(tbl_Ventes[[#This Row],[Cde_Prdt]], tbl_Produits[Cde_Prdt], 0)), "") -> Suppléments
B71: =IFERROR(TEXT(tbl_Ventes[[#This Row],[Date]],"mm-aaaa"),"") -> 01-1900 | D71: =IFERROR( INDEX(tbl_ProduitsRef[Cde_Prdt],MATCH(tbl_Ventes[[#This Row],[Produit]],tbl_ProduitsRef[Produit],0)), "" ) | E71: 0 | F71: =IFERROR( INDEX(tbl_ProduitsRef[Prix Menu],MATCH(tbl_Ventes[[#This Row],[Produit]],tbl_ProduitsRef[Produit],0)), "" ) | G71: =tbl_Ventes[[#This Row],[Qté Vendue]] * IFERROR(_xlfn.XLOOKUP(tbl_Ventes[[#This Row],[Cde_Prdt]], tbl_Produits[Cde_Prdt], tbl_Produits[Prix Menu]), 0) -> 0 | H71: =IFERROR(_xlfn.XLOOKUP(tbl_Ventes[[#This Row],[Cde_Prdt]], tbl_Produits[Cde_Prdt], tbl_Produits[Coût Moyen Portion]), 0) -> 0 | I71: =tbl_Ventes[[#This Row],[Qté Vendue]] * tbl_Ventes[[#This Row],[CMP_par_portion]] -> 0 | J71: =tbl_Ventes[[#This Row],[CA ligne]] - tbl_Ventes[[#This Row],[Coût matière ligne]] -> 0 | K71: =IFERROR(INDEX(tbl_ProduitsRef[Famille], MATCH(tbl_Ventes[[#This Row],[Cde_Prdt]], tbl_Produits[Cde_Prdt], 0)), "")
B72: =IFERROR(TEXT(tbl_Ventes[[#This Row],[Date]],"mm-aaaa"),"") -> 01-1900 | D72: =IFERROR( INDEX(tbl_ProduitsRef[Cde_Prdt],MATCH(tbl_Ventes[[#This Row],[Produit]],tbl_ProduitsRef[Produit],0)), "" ) | E72: 0 | F72: =IFERROR( INDEX(tbl_ProduitsRef[Prix Menu],MATCH(tbl_Ventes[[#This Row],[Produit]],tbl_ProduitsRef[Produit],0)), "" ) | G72: =tbl_Ventes[[#This Row],[Qté Vendue]] * IFERROR(_xlfn.XLOOKUP(tbl_Ventes[[#This Row],[Cde_Prdt]], tbl_Produits[Cde_Prdt], tbl_Produits[Prix Menu]), 0) -> 0 | H72: =IFERROR(_xlfn.XLOOKUP(tbl_Ventes[[#This Row],[Cde_Prdt]], tbl_Produits[Cde_Prdt], tbl_Produits[Coût Moyen Portion]), 0) -> 0 | I72: =tbl_Ventes[[#This Row],[Qté Vendue]] * tbl_Ventes[[#This Row],[CMP_par_portion]] -> 0 | J72: =tbl_Ventes[[#This Row],[CA ligne]] - tbl_Ventes[[#This Row],[Coût matière ligne]] -> 0 | K72: =IFERROR(INDEX(tbl_ProduitsRef[Famille], MATCH(tbl_Ventes[[#This Row],[Cde_Prdt]], tbl_Produits[Cde_Prdt], 0)), "")
B73: =IFERROR(TEXT(tbl_Ventes[[#This Row],[Date]],"mm-aaaa"),"") -> 01-1900 | D73: =IFERROR( INDEX(tbl_ProduitsRef[Cde_Prdt],MATCH(tbl_Ventes[[#This Row],[Produit]],tbl_ProduitsRef[Produit],0)), "" ) | E73: 0 | F73: =IFERROR( INDEX(tbl_ProduitsRef[Prix Menu],MATCH(tbl_Ventes[[#This Row],[Produit]],tbl_ProduitsRef[Produit],0)), "" ) | G73: =tbl_Ventes[[#This Row],[Qté Vendue]] * IFERROR(_xlfn.XLOOKUP(tbl_Ventes[[#This Row],[Cde_Prdt]], tbl_Produits[Cde_Prdt], tbl_Produits[Prix Menu]), 0) -> 0 | H73: =IFERROR(_xlfn.XLOOKUP(tbl_Ventes[[#This Row],[Cde_Prdt]], tbl_Produits[Cde_Prdt], tbl_Produits[Coût Moyen Portion]), 0) -> 0 | I73: =tbl_Ventes[[#This Row],[Qté Vendue]] * tbl_Ventes[[#This Row],[CMP_par_portion]] -> 0 | J73: =tbl_Ventes[[#This Row],[CA ligne]] - tbl_Ventes[[#This Row],[Coût matière ligne]] -> 0 | K73: =IFERROR(INDEX(tbl_ProduitsRef[Famille], MATCH(tbl_Ventes[[#This Row],[Cde_Prdt]], tbl_Produits[Cde_Prdt], 0)), "")
B74: =IFERROR(TEXT(tbl_Ventes[[#This Row],[Date]],"mm-aaaa"),"") -> 01-1900 | D74: =IFERROR( INDEX(tbl_ProduitsRef[Cde_Prdt],MATCH(tbl_Ventes[[#This Row],[Produit]],tbl_ProduitsRef[Produit],0)), "" ) | E74: 0 | F74: =IFERROR( INDEX(tbl_ProduitsRef[Prix Menu],MATCH(tbl_Ventes[[#This Row],[Produit]],tbl_ProduitsRef[Produit],0)), "" ) | G74: =tbl_Ventes[[#This Row],[Qté Vendue]] * IFERROR(_xlfn.XLOOKUP(tbl_Ventes[[#This Row],[Cde_Prdt]], tbl_Produits[Cde_Prdt], tbl_Produits[Prix Menu]), 0) -> 0 | H74: =IFERROR(_xlfn.XLOOKUP(tbl_Ventes[[#This Row],[Cde_Prdt]], tbl_Produits[Cde_Prdt], tbl_Produits[Coût Moyen Portion]), 0) -> 0 | I74: =tbl_Ventes[[#This Row],[Qté Vendue]] * tbl_Ventes[[#This Row],[CMP_par_portion]] -> 0 | J74: =tbl_Ventes[[#This Row],[CA ligne]] - tbl_Ventes[[#This Row],[Coût matière ligne]] -> 0 | K74: =IFERROR(INDEX(tbl_ProduitsRef[Famille], MATCH(tbl_Ventes[[#This Row],[Cde_Prdt]], tbl_Produits[Cde_Prdt], 0)), "")
B75: =IFERROR(TEXT(tbl_Ventes[[#This Row],[Date]],"mm-aaaa"),"") -> 01-1900 | D75: =IFERROR( INDEX(tbl_ProduitsRef[Cde_Prdt],MATCH(tbl_Ventes[[#This Row],[Produit]],tbl_ProduitsRef[Produit],0)), "" ) | E75: 0 | F75: =IFERROR( INDEX(tbl_ProduitsRef[Prix Menu],MATCH(tbl_Ventes[[#This Row],[Produit]],tbl_ProduitsRef[Produit],0)), "" ) | G75: =tbl_Ventes[[#This Row],[Qté Vendue]] * IFERROR(_xlfn.XLOOKUP(tbl_Ventes[[#This Row],[Cde_Prdt]], tbl_Produits[Cde_Prdt], tbl_Produits[Prix Menu]), 0) -> 0 | H75: =IFERROR(_xlfn.XLOOKUP(tbl_Ventes[[#This Row],[Cde_Prdt]], tbl_Produits[Cde_Prdt], tbl_Produits[Coût Moyen Portion]), 0) -> 0 | I75: =tbl_Ventes[[#This Row],[Qté Vendue]] * tbl_Ventes[[#This Row],[CMP_par_portion]] -> 0 | J75: =tbl_Ventes[[#This Row],[CA ligne]] - tbl_Ventes[[#This Row],[Coût matière ligne]] -> 0 | K75: =IFERROR(INDEX(tbl_ProduitsRef[Famille], MATCH(tbl_Ventes[[#This Row],[Cde_Prdt]], tbl_Produits[Cde_Prdt], 0)), "")
B76: =IFERROR(TEXT(tbl_Ventes[[#This Row],[Date]],"mm-aaaa"),"") -> 01-1900 | D76: =IFERROR( INDEX(tbl_ProduitsRef[Cde_Prdt],MATCH(tbl_Ventes[[#This Row],[Produit]],tbl_ProduitsRef[Produit],0)), "" ) | E76: 0 | F76: =IFERROR( INDEX(tbl_ProduitsRef[Prix Menu],MATCH(tbl_Ventes[[#This Row],[Produit]],tbl_ProduitsRef[Produit],0)), "" ) | G76: =tbl_Ventes[[#This Row],[Qté Vendue]] * IFERROR(_xlfn.XLOOKUP(tbl_Ventes[[#This Row],[Cde_Prdt]], tbl_Produits[Cde_Prdt], tbl_Produits[Prix Menu]), 0) -> 0 | H76: =IFERROR(_xlfn.XLOOKUP(tbl_Ventes[[#This Row],[Cde_Prdt]], tbl_Produits[Cde_Prdt], tbl_Produits[Coût Moyen Portion]), 0) -> 0 | I76: =tbl_Ventes[[#This Row],[Qté Vendue]] * tbl_Ventes[[#This Row],[CMP_par_portion]] -> 0 | J76: =tbl_Ventes[[#This Row],[CA ligne]] - tbl_Ventes[[#This Row],[Coût matière ligne]] -> 0 | K76: =IFERROR(INDEX(tbl_ProduitsRef[Famille], MATCH(tbl_Ventes[[#This Row],[Cde_Prdt]], tbl_Produits[Cde_Prdt], 0)), "")
B77: =IFERROR(TEXT(tbl_Ventes[[#This Row],[Date]],"mm-aaaa"),"") -> 01-1900 | D77: =IFERROR( INDEX(tbl_ProduitsRef[Cde_Prdt],MATCH(tbl_Ventes[[#This Row],[Produit]],tbl_ProduitsRef[Produit],0)), "" ) | E77: 0 | F77: =IFERROR( INDEX(tbl_ProduitsRef[Prix Menu],MATCH(tbl_Ventes[[#This Row],[Produit]],tbl_ProduitsRef[Produit],0)), "" ) | G77: =tbl_Ventes[[#This Row],[Qté Vendue]] * IFERROR(_xlfn.XLOOKUP(tbl_Ventes[[#This Row],[Cde_Prdt]], tbl_Produits[Cde_Prdt], tbl_Produits[Prix Menu]), 0) -> 0 | H77: =IFERROR(_xlfn.XLOOKUP(tbl_Ventes[[#This Row],[Cde_Prdt]], tbl_Produits[Cde_Prdt], tbl_Produits[Coût Moyen Portion]), 0) -> 0 | I77: =tbl_Ventes[[#This Row],[Qté Vendue]] * tbl_Ventes[[#This Row],[CMP_par_portion]] -> 0 | J77: =tbl_Ventes[[#This Row],[CA ligne]] - tbl_Ventes[[#This Row],[Coût matière ligne]] -> 0 | K77: =IFERROR(INDEX(tbl_ProduitsRef[Famille], MATCH(tbl_Ventes[[#This Row],[Cde_Prdt]], tbl_Produits[Cde_Prdt], 0)), "")
B78: =IFERROR(TEXT(tbl_Ventes[[#This Row],[Date]],"mm-aaaa"),"") -> 01-1900 | D78: =IFERROR( INDEX(tbl_ProduitsRef[Cde_Prdt],MATCH(tbl_Ventes[[#This Row],[Produit]],tbl_ProduitsRef[Produit],0)), "" ) | E78: 0 | F78: =IFERROR( INDEX(tbl_ProduitsRef[Prix Menu],MATCH(tbl_Ventes[[#This Row],[Produit]],tbl_ProduitsRef[Produit],0)), "" ) | G78: =tbl_Ventes[[#This Row],[Qté Vendue]] * IFERROR(_xlfn.XLOOKUP(tbl_Ventes[[#This Row],[Cde_Prdt]], tbl_Produits[Cde_Prdt], tbl_Produits[Prix Menu]), 0) -> 0 | H78: =IFERROR(_xlfn.XLOOKUP(tbl_Ventes[[#This Row],[Cde_Prdt]], tbl_Produits[Cde_Prdt], tbl_Produits[Coût Moyen Portion]), 0) -> 0 | I78: =tbl_Ventes[[#This Row],[Qté Vendue]] * tbl_Ventes[[#This Row],[CMP_par_portion]] -> 0 | J78: =tbl_Ventes[[#This Row],[CA ligne]] - tbl_Ventes[[#This Row],[Coût matière ligne]] -> 0 | K78: =IFERROR(INDEX(tbl_ProduitsRef[Famille], MATCH(tbl_Ventes[[#This Row],[Cde_Prdt]], tbl_Produits[Cde_Prdt], 0)), "")
B79: =IFERROR(TEXT(tbl_Ventes[[#This Row],[Date]],"mm-aaaa"),"") -> 01-1900 | D79: =IFERROR( INDEX(tbl_ProduitsRef[Cde_Prdt],MATCH(tbl_Ventes[[#This Row],[Produit]],tbl_ProduitsRef[Produit],0)), "" ) | E79: 0 | F79: =IFERROR( INDEX(tbl_ProduitsRef[Prix Menu],MATCH(tbl_Ventes[[#This Row],[Produit]],tbl_ProduitsRef[Produit],0)), "" ) | G79: =tbl_Ventes[[#This Row],[Qté Vendue]] * IFERROR(_xlfn.XLOOKUP(tbl_Ventes[[#This Row],[Cde_Prdt]], tbl_Produits[Cde_Prdt], tbl_Produits[Prix Menu]), 0) -> 0 | H79: =IFERROR(_xlfn.XLOOKUP(tbl_Ventes[[#This Row],[Cde_Prdt]], tbl_Produits[Cde_Prdt], tbl_Produits[Coût Moyen Portion]), 0) -> 0 | I79: =tbl_Ventes[[#This Row],[Qté Vendue]] * tbl_Ventes[[#This Row],[CMP_par_portion]] -> 0 | J79: =tbl_Ventes[[#This Row],[CA ligne]] - tbl_Ventes[[#This Row],[Coût matière ligne]] -> 0 | K79: =IFERROR(INDEX(tbl_ProduitsRef[Famille], MATCH(tbl_Ventes[[#This Row],[Cde_Prdt]], tbl_Produits[Cde_Prdt], 0)), "")
...

Sheet tbl_Charges_Fixes
A1: ID_Charge | B1: Colonne1 | C1: Libellé | D1: Famille affectée | E1: Montant_Mensuel | F1: Fréquence | G1: Type d’affectation
A2: CHA001 | B2: Occupation | C2: Loyer local | D2: Globale | E2: 200000 | F2: Mensuelle | G2: Globale
A3: CHA002 | B3: Occupation | C3: Assurance local | D3: Globale | E3: 1300 | F3: Mensuelle | G3: Globale
A4: CHA003 | B4: Salaires | C4: Assurance Salariés (AT+Transport) | D4: Globale | E4: 2900 | F4: Mensuelle | G4: Globale
A5: CHA004 | B5: Salaires | C5: Salaires Petits déjeuners | D5: Petits déjeuners | E5: =6*4000 -> 24000 | F5: Mensuelle | G5: Spécifique
A6: CHA005 | B6: Salaires | C6: Salaires Œufs & Omelettes | D6: Œufs & Omelettes | E6: =+E5 -> 24000 | F6: Mensuelle | G6: Spécifique
A7: CHA006 | B7: Salaires | C7: Salaires à la carte | D7: à la carte | E7: =+E6 -> 24000 | F7: Mensuelle | G7: Spécifique
A8: CHA007 | B8: Salaires | C8: Salaires Sérveur | D8: Globale | E8: =60*3000 -> 180000 | F8: Mensuelle | G8: Globale
A9: CHA008 | B9: Salaires | C9: Salaires Entrées & Salades | D9: Entrées & Salades | E9: =8*5000 -> 40000 | F9: Mensuelle | G9: Spécifique
A10: CHA009 | B10: Salaires | C10: Salaires Poulet | D10: Poulet | E10: =4*6000 -> 24000 | F10: Mensuelle | G10: Spécifique
A11: CHA011 | B11: Salaires | C11: Salaires Boucherie | D11: Boucherie | E11: 6540 | F11: Mensuelle | G11: Spécifique
A12: CHA012 | B12: Salaires | C12: Salaires Poissons & Fruits de mer | D12: Poissons & Fruits de mer | E12: 6555 | F12: Mensuelle | G12: Spécifique
A13: CHA013 | B13: Salaires | C13: Salaires Tajines & Coin marocain | D13: Tajines & Coin marocain | E13: 65555 | F13: Mensuelle | G13: Spécifique
A14: CHA014 | B14: Salaires | C14: Salaires Pâtes | D14: Pâtes | E14: 21000 | F14: Mensuelle | G14: Spécifique
A15: CHA015 | B15: Salaires | C15: Salaires Pizzas | D15: Pizzas | E15: 21000 | F15: Mensuelle | G15: Spécifique
A16: CHA016 | B16: Salaires | C16: Salaires Snack | D16: Snack | E16: 20000 | F16: Mensuelle | G16: Spécifique
A17: CHA017 | B17: Salaires | C17: Salaires Glaces & Desserts | D17: Glaces & Desserts | E17: 5000 | F17: Mensuelle | G17: Spécifique
A18: CHA018 | B18: Salaires | C18: Salaires Crêpes & Gaufres | D18: Crêpes & Gaufres | E18: 15000 | F18: Mensuelle | G18: Spécifique
A19: CHA019 | B19: Salaires | C19: Salaires Boissons chaudes | D19: Boissons chaudes | E19: 35000 | F19: Mensuelle | G19: Spécifique
A20: CHA020 | B20: Salaires | C20: Salaires Jus Frais | D20: Jus Frais | E20: 14000 | F20: Mensuelle | G20: Spécifique
A21: CHA021 | B21: Salaires | C21: Salaires Milkshakes | D21: Milkshakes | E21: 35000 | F21: Mensuelle | G21: Spécifique
A22: CHA022 | B22: Salaires | C22: Salaires Smoothies & Coctails | D22: Smoothies & Coctails | E22: 10000 | F22: Mensuelle | G22: Spécifique
A23: CHA023 | B23: Salaires | C23: Salaires Boissons froides | D23: Boissons froides | E23: 40000 | F23: Mensuelle | G23: Spécifique
A24: CHA024 | B24: Salaires | C24: Charges patronales | D24: Globale | E24: =SUM(E6:E10)*12.6% -> 36792 | F24: Mensuelle | G24: Globale
A25: CHA025 | B25: Salaires | C25: Avantages salariés (repas, remises) | D25: Globale | E25: 1200 | F25: Mensuelle | G25: Globale
A26: CHA026 | B26: Salaires | C26: Avantages salariés (repas, remises) | D26: Globale | E26: 1200 | F26: Mensuelle | G26: Globale
A27: CHA027 | B27: Salaires | C27: Avantages salariés (repas, remises) | D27: Globale | E27: 1200 | F27: Mensuelle | G27: Globale
A28: CHA028 | B28: Salaires | C28: Avantages salariés (repas, remises) | D28: Globale | E28: 1200 | F28: Mensuelle | G28: Globale
A29: CHA029 | B29: Energie | C29: Électricité | D29: Globale | E29: 7000 | F29: Mensuelle | G29: Globale
A30: CHA030 | B30: Energie | C30: Gaz / cuisson | D30: Globale | E30: 5000 | F30: Mensuelle | G30: Globale
A31: CHA031 | B31: Eau & Assainissement | C31: Eau | D31: Globale | E31: 2500 | F31: Mensuelle | G31: Globale
A32: CHA032 | B32: Entretien | C32: Maintenance équipements | D32: Globale | E32: 6000 | F32: Mensuelle | G32: Globale
A33: CHA033 | B33: Entretien | C33: Nettoyage & produits entretien | D33: Globale | E33: 25000 | F33: Mensuelle | G33: Globale
A34: CHA034 | B34: Fournitures | C34: Vaisselle jetable & consommables | D34: Globale | E34: 5000 | F34: Mensuelle | G34: Globale
A35: CHA035 | B35: Fournitures | C35: Papeterie, menus, fournitures admin | D35: Globale | E35: 3000 | F35: Mensuelle | G35: Globale
A36: CHA036 | B36: Marketing | C36: Publicité & réseaux sociaux | D36: Globale | E36: 3500 | F36: Mensuelle | G36: Globale
... A43: CHA043 | B43: Divers / Réserve | C43: Provision imprévus / SAV | D43: Globale | E43: 10000 | F43: Mensuelle | G43: Globale
E44: =SUBTOTAL(109,tbl_Charges_Fixes[Montant_Mensuel]) -> 929242
E47: Charge Globale | F47: Charge Spécifique | G47: total des charges globales
E48: =SUMIFS(tbl_Charges_Fixes[Montant_Mensuel], tbl_Charges_Fixes[Type d’affectation], "Globale") -> 498592 | F48: =SUMIFS(tbl_Charges_Fixes[Montant_Mensuel], tbl_Charges_Fixes[Type d’affectation], "Spécifique") -> 430650 | G48: =SUM(E48:F48) -> 929242
...

Sheet tbl_Produits
